Watching for file changes with StatReloader
Watching for file changes with StatReloader
Invalid HTTP_HOST header: '127.0.0.1:8000'. You may need to add '127.0.0.1' to ALLOWED_HOSTS.
Traceback (most recent call last):
  File "C:\Users\Seanb\miniconda3\envs\webmap\lib\site-packages\django\core\handlers\exception.py", line 55, in inner
    response = get_response(request)
  File "C:\Users\Seanb\miniconda3\envs\webmap\lib\site-packages\django\utils\deprecation.py", line 133, in __call__
    response = self.process_request(request)
  File "C:\Users\Seanb\miniconda3\envs\webmap\lib\site-packages\django\middleware\common.py", line 48, in process_request
    host = request.get_host()
  File "C:\Users\Seanb\miniconda3\envs\webmap\lib\site-packages\django\http\request.py", line 150, in get_host
    raise DisallowedHost(msg)
django.core.exceptions.DisallowedHost: Invalid HTTP_HOST header: '127.0.0.1:8000'. You may need to add '127.0.0.1' to ALLOWED_HOSTS.
Bad Request: /
Invalid HTTP_HOST header: '127.0.0.1:8000'. You may need to add '127.0.0.1' to ALLOWED_HOSTS.
Traceback (most recent call last):
  File "C:\Users\Seanb\miniconda3\envs\webmap\lib\site-packages\django\core\handlers\exception.py", line 55, in inner
    response = get_response(request)
  File "C:\Users\Seanb\miniconda3\envs\webmap\lib\site-packages\django\utils\deprecation.py", line 133, in __call__
    response = self.process_request(request)
  File "C:\Users\Seanb\miniconda3\envs\webmap\lib\site-packages\django\middleware\common.py", line 48, in process_request
    host = request.get_host()
  File "C:\Users\Seanb\miniconda3\envs\webmap\lib\site-packages\django\http\request.py", line 150, in get_host
    raise DisallowedHost(msg)
django.core.exceptions.DisallowedHost: Invalid HTTP_HOST header: '127.0.0.1:8000'. You may need to add '127.0.0.1' to ALLOWED_HOSTS.
Bad Request: /favicon.ico
Invalid HTTP_HOST header: '127.0.0.1:8000'. You may need to add '127.0.0.1' to ALLOWED_HOSTS.
Traceback (most recent call last):
  File "C:\Users\Seanb\miniconda3\envs\webmap\lib\site-packages\django\core\handlers\exception.py", line 55, in inner
    response = get_response(request)
  File "C:\Users\Seanb\miniconda3\envs\webmap\lib\site-packages\django\utils\deprecation.py", line 133, in __call__
    response = self.process_request(request)
  File "C:\Users\Seanb\miniconda3\envs\webmap\lib\site-packages\django\middleware\common.py", line 48, in process_request
    host = request.get_host()
  File "C:\Users\Seanb\miniconda3\envs\webmap\lib\site-packages\django\http\request.py", line 150, in get_host
    raise DisallowedHost(msg)
django.core.exceptions.DisallowedHost: Invalid HTTP_HOST header: '127.0.0.1:8000'. You may need to add '127.0.0.1' to ALLOWED_HOSTS.
Bad Request: /trails
Invalid HTTP_HOST header: '127.0.0.1:8000'. You may need to add '127.0.0.1' to ALLOWED_HOSTS.
Traceback (most recent call last):
  File "C:\Users\Seanb\miniconda3\envs\webmap\lib\site-packages\django\core\handlers\exception.py", line 55, in inner
    response = get_response(request)
  File "C:\Users\Seanb\miniconda3\envs\webmap\lib\site-packages\django\utils\deprecation.py", line 133, in __call__
    response = self.process_request(request)
  File "C:\Users\Seanb\miniconda3\envs\webmap\lib\site-packages\django\middleware\common.py", line 48, in process_request
    host = request.get_host()
  File "C:\Users\Seanb\miniconda3\envs\webmap\lib\site-packages\django\http\request.py", line 150, in get_host
    raise DisallowedHost(msg)
django.core.exceptions.DisallowedHost: Invalid HTTP_HOST header: '127.0.0.1:8000'. You may need to add '127.0.0.1' to ALLOWED_HOSTS.
Bad Request: /favicon.ico
Invalid HTTP_HOST header: '127.0.0.1:8000'. You may need to add '127.0.0.1' to ALLOWED_HOSTS.
Traceback (most recent call last):
  File "C:\Users\Seanb\miniconda3\envs\webmap\lib\site-packages\django\core\handlers\exception.py", line 55, in inner
    response = get_response(request)
  File "C:\Users\Seanb\miniconda3\envs\webmap\lib\site-packages\django\utils\deprecation.py", line 133, in __call__
    response = self.process_request(request)
  File "C:\Users\Seanb\miniconda3\envs\webmap\lib\site-packages\django\middleware\common.py", line 48, in process_request
    host = request.get_host()
  File "C:\Users\Seanb\miniconda3\envs\webmap\lib\site-packages\django\http\request.py", line 150, in get_host
    raise DisallowedHost(msg)
django.core.exceptions.DisallowedHost: Invalid HTTP_HOST header: '127.0.0.1:8000'. You may need to add '127.0.0.1' to ALLOWED_HOSTS.
Bad Request: /trails
Invalid HTTP_HOST header: '127.0.0.1:8000'. You may need to add '127.0.0.1' to ALLOWED_HOSTS.
Traceback (most recent call last):
  File "C:\Users\Seanb\miniconda3\envs\webmap\lib\site-packages\django\core\handlers\exception.py", line 55, in inner
    response = get_response(request)
  File "C:\Users\Seanb\miniconda3\envs\webmap\lib\site-packages\django\utils\deprecation.py", line 133, in __call__
    response = self.process_request(request)
  File "C:\Users\Seanb\miniconda3\envs\webmap\lib\site-packages\django\middleware\common.py", line 48, in process_request
    host = request.get_host()
  File "C:\Users\Seanb\miniconda3\envs\webmap\lib\site-packages\django\http\request.py", line 150, in get_host
    raise DisallowedHost(msg)
django.core.exceptions.DisallowedHost: Invalid HTTP_HOST header: '127.0.0.1:8000'. You may need to add '127.0.0.1' to ALLOWED_HOSTS.
Bad Request: /favicon.ico
Invalid HTTP_HOST header: '127.0.0.1:8000'. You may need to add '127.0.0.1' to ALLOWED_HOSTS.
Traceback (most recent call last):
  File "C:\Users\Seanb\miniconda3\envs\webmap\lib\site-packages\django\core\handlers\exception.py", line 55, in inner
    response = get_response(request)
  File "C:\Users\Seanb\miniconda3\envs\webmap\lib\site-packages\django\utils\deprecation.py", line 133, in __call__
    response = self.process_request(request)
  File "C:\Users\Seanb\miniconda3\envs\webmap\lib\site-packages\django\middleware\common.py", line 48, in process_request
    host = request.get_host()
  File "C:\Users\Seanb\miniconda3\envs\webmap\lib\site-packages\django\http\request.py", line 150, in get_host
    raise DisallowedHost(msg)
django.core.exceptions.DisallowedHost: Invalid HTTP_HOST header: '127.0.0.1:8000'. You may need to add '127.0.0.1' to ALLOWED_HOSTS.
Bad Request: /trails
Invalid HTTP_HOST header: '127.0.0.1:8000'. You may need to add '127.0.0.1' to ALLOWED_HOSTS.
Traceback (most recent call last):
  File "C:\Users\Seanb\miniconda3\envs\webmap\lib\site-packages\django\core\handlers\exception.py", line 55, in inner
    response = get_response(request)
  File "C:\Users\Seanb\miniconda3\envs\webmap\lib\site-packages\django\utils\deprecation.py", line 133, in __call__
    response = self.process_request(request)
  File "C:\Users\Seanb\miniconda3\envs\webmap\lib\site-packages\django\middleware\common.py", line 48, in process_request
    host = request.get_host()
  File "C:\Users\Seanb\miniconda3\envs\webmap\lib\site-packages\django\http\request.py", line 150, in get_host
    raise DisallowedHost(msg)
django.core.exceptions.DisallowedHost: Invalid HTTP_HOST header: '127.0.0.1:8000'. You may need to add '127.0.0.1' to ALLOWED_HOSTS.
Bad Request: /favicon.ico
Invalid HTTP_HOST header: '127.0.0.1:8000'. You may need to add '127.0.0.1' to ALLOWED_HOSTS.
Traceback (most recent call last):
  File "C:\Users\Seanb\miniconda3\envs\webmap\lib\site-packages\django\core\handlers\exception.py", line 55, in inner
    response = get_response(request)
  File "C:\Users\Seanb\miniconda3\envs\webmap\lib\site-packages\django\utils\deprecation.py", line 133, in __call__
    response = self.process_request(request)
  File "C:\Users\Seanb\miniconda3\envs\webmap\lib\site-packages\django\middleware\common.py", line 48, in process_request
    host = request.get_host()
  File "C:\Users\Seanb\miniconda3\envs\webmap\lib\site-packages\django\http\request.py", line 150, in get_host
    raise DisallowedHost(msg)
django.core.exceptions.DisallowedHost: Invalid HTTP_HOST header: '127.0.0.1:8000'. You may need to add '127.0.0.1' to ALLOWED_HOSTS.
Bad Request: /trails
Invalid HTTP_HOST header: '127.0.0.1:8000'. You may need to add '127.0.0.1' to ALLOWED_HOSTS.
Traceback (most recent call last):
  File "C:\Users\Seanb\miniconda3\envs\webmap\lib\site-packages\django\core\handlers\exception.py", line 55, in inner
    response = get_response(request)
  File "C:\Users\Seanb\miniconda3\envs\webmap\lib\site-packages\django\utils\deprecation.py", line 133, in __call__
    response = self.process_request(request)
  File "C:\Users\Seanb\miniconda3\envs\webmap\lib\site-packages\django\middleware\common.py", line 48, in process_request
    host = request.get_host()
  File "C:\Users\Seanb\miniconda3\envs\webmap\lib\site-packages\django\http\request.py", line 150, in get_host
    raise DisallowedHost(msg)
django.core.exceptions.DisallowedHost: Invalid HTTP_HOST header: '127.0.0.1:8000'. You may need to add '127.0.0.1' to ALLOWED_HOSTS.
Bad Request: /favicon.ico
Watching for file changes with StatReloader
Invalid HTTP_HOST header: '127.0.0.1:8000'. You may need to add '127.0.0.1' to ALLOWED_HOSTS.
Traceback (most recent call last):
  File "C:\Users\Seanb\miniconda3\envs\webmap\lib\site-packages\django\core\handlers\exception.py", line 55, in inner
    response = get_response(request)
  File "C:\Users\Seanb\miniconda3\envs\webmap\lib\site-packages\django\utils\deprecation.py", line 133, in __call__
    response = self.process_request(request)
  File "C:\Users\Seanb\miniconda3\envs\webmap\lib\site-packages\django\middleware\common.py", line 48, in process_request
    host = request.get_host()
  File "C:\Users\Seanb\miniconda3\envs\webmap\lib\site-packages\django\http\request.py", line 150, in get_host
    raise DisallowedHost(msg)
django.core.exceptions.DisallowedHost: Invalid HTTP_HOST header: '127.0.0.1:8000'. You may need to add '127.0.0.1' to ALLOWED_HOSTS.
Bad Request: /
Invalid HTTP_HOST header: '127.0.0.1:8000'. You may need to add '127.0.0.1' to ALLOWED_HOSTS.
Traceback (most recent call last):
  File "C:\Users\Seanb\miniconda3\envs\webmap\lib\site-packages\django\core\handlers\exception.py", line 55, in inner
    response = get_response(request)
  File "C:\Users\Seanb\miniconda3\envs\webmap\lib\site-packages\django\utils\deprecation.py", line 133, in __call__
    response = self.process_request(request)
  File "C:\Users\Seanb\miniconda3\envs\webmap\lib\site-packages\django\middleware\common.py", line 48, in process_request
    host = request.get_host()
  File "C:\Users\Seanb\miniconda3\envs\webmap\lib\site-packages\django\http\request.py", line 150, in get_host
    raise DisallowedHost(msg)
django.core.exceptions.DisallowedHost: Invalid HTTP_HOST header: '127.0.0.1:8000'. You may need to add '127.0.0.1' to ALLOWED_HOSTS.
Bad Request: /favicon.ico
Invalid HTTP_HOST header: '127.0.0.1:8000'. You may need to add '127.0.0.1' to ALLOWED_HOSTS.
Traceback (most recent call last):
  File "C:\Users\Seanb\miniconda3\envs\webmap\lib\site-packages\django\core\handlers\exception.py", line 55, in inner
    response = get_response(request)
  File "C:\Users\Seanb\miniconda3\envs\webmap\lib\site-packages\django\utils\deprecation.py", line 133, in __call__
    response = self.process_request(request)
  File "C:\Users\Seanb\miniconda3\envs\webmap\lib\site-packages\django\middleware\common.py", line 48, in process_request
    host = request.get_host()
  File "C:\Users\Seanb\miniconda3\envs\webmap\lib\site-packages\django\http\request.py", line 150, in get_host
    raise DisallowedHost(msg)
django.core.exceptions.DisallowedHost: Invalid HTTP_HOST header: '127.0.0.1:8000'. You may need to add '127.0.0.1' to ALLOWED_HOSTS.
Bad Request: /
Invalid HTTP_HOST header: '127.0.0.1:8000'. You may need to add '127.0.0.1' to ALLOWED_HOSTS.
Traceback (most recent call last):
  File "C:\Users\Seanb\miniconda3\envs\webmap\lib\site-packages\django\core\handlers\exception.py", line 55, in inner
    response = get_response(request)
  File "C:\Users\Seanb\miniconda3\envs\webmap\lib\site-packages\django\utils\deprecation.py", line 133, in __call__
    response = self.process_request(request)
  File "C:\Users\Seanb\miniconda3\envs\webmap\lib\site-packages\django\middleware\common.py", line 48, in process_request
    host = request.get_host()
  File "C:\Users\Seanb\miniconda3\envs\webmap\lib\site-packages\django\http\request.py", line 150, in get_host
    raise DisallowedHost(msg)
django.core.exceptions.DisallowedHost: Invalid HTTP_HOST header: '127.0.0.1:8000'. You may need to add '127.0.0.1' to ALLOWED_HOSTS.
Bad Request: /favicon.ico
Invalid HTTP_HOST header: '127.0.0.1:8000'. You may need to add '127.0.0.1' to ALLOWED_HOSTS.
Traceback (most recent call last):
  File "C:\Users\Seanb\miniconda3\envs\webmap\lib\site-packages\django\core\handlers\exception.py", line 55, in inner
    response = get_response(request)
  File "C:\Users\Seanb\miniconda3\envs\webmap\lib\site-packages\django\utils\deprecation.py", line 133, in __call__
    response = self.process_request(request)
  File "C:\Users\Seanb\miniconda3\envs\webmap\lib\site-packages\django\middleware\common.py", line 48, in process_request
    host = request.get_host()
  File "C:\Users\Seanb\miniconda3\envs\webmap\lib\site-packages\django\http\request.py", line 150, in get_host
    raise DisallowedHost(msg)
django.core.exceptions.DisallowedHost: Invalid HTTP_HOST header: '127.0.0.1:8000'. You may need to add '127.0.0.1' to ALLOWED_HOSTS.
Bad Request: /
Invalid HTTP_HOST header: '127.0.0.1:8000'. You may need to add '127.0.0.1' to ALLOWED_HOSTS.
Traceback (most recent call last):
  File "C:\Users\Seanb\miniconda3\envs\webmap\lib\site-packages\django\core\handlers\exception.py", line 55, in inner
    response = get_response(request)
  File "C:\Users\Seanb\miniconda3\envs\webmap\lib\site-packages\django\utils\deprecation.py", line 133, in __call__
    response = self.process_request(request)
  File "C:\Users\Seanb\miniconda3\envs\webmap\lib\site-packages\django\middleware\common.py", line 48, in process_request
    host = request.get_host()
  File "C:\Users\Seanb\miniconda3\envs\webmap\lib\site-packages\django\http\request.py", line 150, in get_host
    raise DisallowedHost(msg)
django.core.exceptions.DisallowedHost: Invalid HTTP_HOST header: '127.0.0.1:8000'. You may need to add '127.0.0.1' to ALLOWED_HOSTS.
Bad Request: /favicon.ico
C:\Users\Seanb\PycharmProjects\CA_1\CA_1\settings.py changed, reloading.
Watching for file changes with StatReloader
Watching for file changes with StatReloader
Invalid HTTP_HOST header: '127.0.0.1:8000'. You may need to add '127.0.0.1' to ALLOWED_HOSTS.
Traceback (most recent call last):
  File "C:\Users\Seanb\miniconda3\envs\webmap\lib\site-packages\django\core\handlers\exception.py", line 55, in inner
    response = get_response(request)
  File "C:\Users\Seanb\miniconda3\envs\webmap\lib\site-packages\django\utils\deprecation.py", line 133, in __call__
    response = self.process_request(request)
  File "C:\Users\Seanb\miniconda3\envs\webmap\lib\site-packages\django\middleware\common.py", line 48, in process_request
    host = request.get_host()
  File "C:\Users\Seanb\miniconda3\envs\webmap\lib\site-packages\django\http\request.py", line 150, in get_host
    raise DisallowedHost(msg)
django.core.exceptions.DisallowedHost: Invalid HTTP_HOST header: '127.0.0.1:8000'. You may need to add '127.0.0.1' to ALLOWED_HOSTS.
Bad Request: /
Invalid HTTP_HOST header: '127.0.0.1:8000'. You may need to add '127.0.0.1' to ALLOWED_HOSTS.
Traceback (most recent call last):
  File "C:\Users\Seanb\miniconda3\envs\webmap\lib\site-packages\django\core\handlers\exception.py", line 55, in inner
    response = get_response(request)
  File "C:\Users\Seanb\miniconda3\envs\webmap\lib\site-packages\django\utils\deprecation.py", line 133, in __call__
    response = self.process_request(request)
  File "C:\Users\Seanb\miniconda3\envs\webmap\lib\site-packages\django\middleware\common.py", line 48, in process_request
    host = request.get_host()
  File "C:\Users\Seanb\miniconda3\envs\webmap\lib\site-packages\django\http\request.py", line 150, in get_host
    raise DisallowedHost(msg)
django.core.exceptions.DisallowedHost: Invalid HTTP_HOST header: '127.0.0.1:8000'. You may need to add '127.0.0.1' to ALLOWED_HOSTS.
Bad Request: /favicon.ico
C:\Users\Seanb\PycharmProjects\CA_1\CA_1\settings.py changed, reloading.
Watching for file changes with StatReloader
Invalid HTTP_HOST header: '127.0.0.1:8000'. You may need to add '127.0.0.1' to ALLOWED_HOSTS.
Traceback (most recent call last):
  File "C:\Users\Seanb\miniconda3\envs\webmap\lib\site-packages\django\core\handlers\exception.py", line 55, in inner
    response = get_response(request)
  File "C:\Users\Seanb\miniconda3\envs\webmap\lib\site-packages\django\utils\deprecation.py", line 133, in __call__
    response = self.process_request(request)
  File "C:\Users\Seanb\miniconda3\envs\webmap\lib\site-packages\django\middleware\common.py", line 48, in process_request
    host = request.get_host()
  File "C:\Users\Seanb\miniconda3\envs\webmap\lib\site-packages\django\http\request.py", line 150, in get_host
    raise DisallowedHost(msg)
django.core.exceptions.DisallowedHost: Invalid HTTP_HOST header: '127.0.0.1:8000'. You may need to add '127.0.0.1' to ALLOWED_HOSTS.
Bad Request: /
Invalid HTTP_HOST header: '127.0.0.1:8000'. You may need to add '127.0.0.1' to ALLOWED_HOSTS.
Traceback (most recent call last):
  File "C:\Users\Seanb\miniconda3\envs\webmap\lib\site-packages\django\core\handlers\exception.py", line 55, in inner
    response = get_response(request)
  File "C:\Users\Seanb\miniconda3\envs\webmap\lib\site-packages\django\utils\deprecation.py", line 133, in __call__
    response = self.process_request(request)
  File "C:\Users\Seanb\miniconda3\envs\webmap\lib\site-packages\django\middleware\common.py", line 48, in process_request
    host = request.get_host()
  File "C:\Users\Seanb\miniconda3\envs\webmap\lib\site-packages\django\http\request.py", line 150, in get_host
    raise DisallowedHost(msg)
django.core.exceptions.DisallowedHost: Invalid HTTP_HOST header: '127.0.0.1:8000'. You may need to add '127.0.0.1' to ALLOWED_HOSTS.
Bad Request: /favicon.ico
Invalid HTTP_HOST header: '127.0.0.1:8000'. You may need to add '127.0.0.1' to ALLOWED_HOSTS.
Traceback (most recent call last):
  File "C:\Users\Seanb\miniconda3\envs\webmap\lib\site-packages\django\core\handlers\exception.py", line 55, in inner
    response = get_response(request)
  File "C:\Users\Seanb\miniconda3\envs\webmap\lib\site-packages\django\utils\deprecation.py", line 133, in __call__
    response = self.process_request(request)
  File "C:\Users\Seanb\miniconda3\envs\webmap\lib\site-packages\django\middleware\common.py", line 48, in process_request
    host = request.get_host()
  File "C:\Users\Seanb\miniconda3\envs\webmap\lib\site-packages\django\http\request.py", line 150, in get_host
    raise DisallowedHost(msg)
django.core.exceptions.DisallowedHost: Invalid HTTP_HOST header: '127.0.0.1:8000'. You may need to add '127.0.0.1' to ALLOWED_HOSTS.
Bad Request: /trails
Invalid HTTP_HOST header: '127.0.0.1:8000'. You may need to add '127.0.0.1' to ALLOWED_HOSTS.
Traceback (most recent call last):
  File "C:\Users\Seanb\miniconda3\envs\webmap\lib\site-packages\django\core\handlers\exception.py", line 55, in inner
    response = get_response(request)
  File "C:\Users\Seanb\miniconda3\envs\webmap\lib\site-packages\django\utils\deprecation.py", line 133, in __call__
    response = self.process_request(request)
  File "C:\Users\Seanb\miniconda3\envs\webmap\lib\site-packages\django\middleware\common.py", line 48, in process_request
    host = request.get_host()
  File "C:\Users\Seanb\miniconda3\envs\webmap\lib\site-packages\django\http\request.py", line 150, in get_host
    raise DisallowedHost(msg)
django.core.exceptions.DisallowedHost: Invalid HTTP_HOST header: '127.0.0.1:8000'. You may need to add '127.0.0.1' to ALLOWED_HOSTS.
Bad Request: /favicon.ico
Watching for file changes with StatReloader
Invalid HTTP_HOST header: '127.0.0.1:8000'. You may need to add '127.0.0.1' to ALLOWED_HOSTS.
Traceback (most recent call last):
  File "C:\Users\Seanb\miniconda3\envs\webmap\lib\site-packages\django\core\handlers\exception.py", line 55, in inner
    response = get_response(request)
  File "C:\Users\Seanb\miniconda3\envs\webmap\lib\site-packages\django\utils\deprecation.py", line 133, in __call__
    response = self.process_request(request)
  File "C:\Users\Seanb\miniconda3\envs\webmap\lib\site-packages\django\middleware\common.py", line 48, in process_request
    host = request.get_host()
  File "C:\Users\Seanb\miniconda3\envs\webmap\lib\site-packages\django\http\request.py", line 150, in get_host
    raise DisallowedHost(msg)
django.core.exceptions.DisallowedHost: Invalid HTTP_HOST header: '127.0.0.1:8000'. You may need to add '127.0.0.1' to ALLOWED_HOSTS.
Bad Request: /
Invalid HTTP_HOST header: '127.0.0.1:8000'. You may need to add '127.0.0.1' to ALLOWED_HOSTS.
Traceback (most recent call last):
  File "C:\Users\Seanb\miniconda3\envs\webmap\lib\site-packages\django\core\handlers\exception.py", line 55, in inner
    response = get_response(request)
  File "C:\Users\Seanb\miniconda3\envs\webmap\lib\site-packages\django\utils\deprecation.py", line 133, in __call__
    response = self.process_request(request)
  File "C:\Users\Seanb\miniconda3\envs\webmap\lib\site-packages\django\middleware\common.py", line 48, in process_request
    host = request.get_host()
  File "C:\Users\Seanb\miniconda3\envs\webmap\lib\site-packages\django\http\request.py", line 150, in get_host
    raise DisallowedHost(msg)
django.core.exceptions.DisallowedHost: Invalid HTTP_HOST header: '127.0.0.1:8000'. You may need to add '127.0.0.1' to ALLOWED_HOSTS.
Bad Request: /favicon.ico
C:\Users\Seanb\PycharmProjects\CA_1\CA_1\settings.py changed, reloading.
Watching for file changes with StatReloader
Not Found: /
Not Found: /favicon.ico
GDAL_ERROR 1: b'PROJ: proj_create_from_database: Cannot find proj.db'
GDAL_ERROR 1: b'PROJ: proj_create_from_database: Cannot find proj.db'
GDAL_ERROR 1: b'PROJ: proj_create_from_database: Cannot find proj.db'
GDAL_ERROR 1: b'PROJ: proj_create_from_database: Cannot find proj.db'
GDAL_ERROR 1: b'PROJ: proj_create_from_database: Cannot find proj.db'
GDAL_ERROR 1: b'PROJ: proj_create_from_database: Cannot find proj.db'
GDAL_ERROR 1: b'PROJ: proj_create_from_database: Cannot find proj.db'
GDAL_ERROR 1: b'PROJ: proj_create_from_database: Cannot find proj.db'
GDAL_ERROR 1: b'PROJ: proj_create_from_database: Cannot find proj.db'
GDAL_ERROR 1: b'PROJ: proj_create_from_database: Cannot find proj.db'
GDAL_ERROR 1: b'PROJ: proj_create_from_database: Cannot find proj.db'
GDAL_ERROR 1: b'PROJ: proj_create_from_database: Cannot find proj.db'
Not Found: /accounts/login/
Not Found: /accounts/login/
Not Found: /accounts/login/
GDAL_ERROR 1: b'PROJ: proj_create_from_database: Cannot find proj.db'
GDAL_ERROR 1: b'PROJ: proj_create_from_database: Cannot find proj.db'
GDAL_ERROR 1: b'PROJ: proj_create_from_database: Cannot find proj.db'
GDAL_ERROR 1: b'PROJ: proj_create_from_database: Cannot find proj.db'
GDAL_ERROR 1: b'PROJ: proj_create_from_database: Cannot find proj.db'
GDAL_ERROR 1: b'PROJ: proj_create_from_database: Cannot find proj.db'
GDAL_ERROR 1: b'PROJ: proj_create_from_database: Cannot find proj.db'
Not Found: /accounts/login/
GDAL_ERROR 1: b'PROJ: proj_create_from_database: Cannot find proj.db'
GDAL_ERROR 1: b'PROJ: proj_create_from_database: Cannot find proj.db'
GDAL_ERROR 1: b'PROJ: proj_create_from_database: Cannot find proj.db'
Watching for file changes with StatReloader
Not Found: /
GDAL_ERROR 1: b'PROJ: proj_create_from_database: Cannot find proj.db'
GDAL_ERROR 1: b'PROJ: proj_create_from_database: Cannot find proj.db'
GDAL_ERROR 1: b'PROJ: proj_create_from_database: Cannot find proj.db'
Not Found: /accounts/login/
GDAL_ERROR 1: b'PROJ: proj_create_from_database: Cannot find proj.db'
GDAL_ERROR 1: b'PROJ: proj_create_from_database: Cannot find proj.db'
GDAL_ERROR 1: b'PROJ: proj_create_from_database: Cannot find proj.db'
GDAL_ERROR 1: b'PROJ: proj_create_from_database: Cannot find proj.db'
Watching for file changes with StatReloader
Not Found: /
GDAL_ERROR 1: b'PROJ: proj_create_from_database: Cannot find proj.db'
GDAL_ERROR 1: b'PROJ: proj_create_from_database: Cannot find proj.db'
GDAL_ERROR 1: b'PROJ: proj_create_from_database: Cannot find proj.db'
GDAL_ERROR 1: b'PROJ: proj_create_from_database: Cannot find proj.db'
C:\Users\Seanb\PycharmProjects\CA_1\CA_1\settings.py changed, reloading.
Watching for file changes with StatReloader
GDAL_ERROR 1: b'PROJ: proj_create_from_database: Cannot find proj.db'
GDAL_ERROR 1: b'PROJ: proj_create_from_database: Cannot find proj.db'
C:\Users\Seanb\PycharmProjects\CA_1\CA_1\settings.py changed, reloading.
Watching for file changes with StatReloader
GDAL_ERROR 1: b'PROJ: proj_create_from_database: Cannot find proj.db'
C:\Users\Seanb\PycharmProjects\CA_1\CA_1\settings.py changed, reloading.
Watching for file changes with StatReloader
C:\Users\Seanb\PycharmProjects\CA_1\CA_1\settings.py changed, reloading.
Watching for file changes with StatReloader
C:\Users\Seanb\PycharmProjects\CA_1\CA_1\urls.py changed, reloading.
Watching for file changes with StatReloader
C:\Users\Seanb\PycharmProjects\CA_1\CA_1\urls.py changed, reloading.
Watching for file changes with StatReloader
GDAL_ERROR 1: b'PROJ: proj_create_from_database: Cannot find proj.db'
GDAL_ERROR 1: b'PROJ: proj_create_from_database: Cannot find proj.db'
GDAL_ERROR 1: b'PROJ: proj_create_from_database: Cannot find proj.db'
C:\Users\Seanb\PycharmProjects\CA_1\CA_1\settings.py changed, reloading.
Watching for file changes with StatReloader
GDAL_ERROR 1: b'PROJ: proj_create_from_database: Cannot find proj.db'
C:\Users\Seanb\PycharmProjects\CA_1\CA_1\settings.py changed, reloading.
Watching for file changes with StatReloader
GDAL_ERROR 1: b'PROJ: proj_create_from_database: Cannot find proj.db'
GDAL_ERROR 1: b'PROJ: proj_create_from_database: Cannot find proj.db'
C:\Users\Seanb\PycharmProjects\CA_1\CA_1\settings.py changed, reloading.
Watching for file changes with StatReloader
GDAL_ERROR 1: b'PROJ: proj_create_from_database: Cannot find proj.db'
Watching for file changes with StatReloader
/usr/src/app/CA_1/settings.py changed, reloading.
Watching for file changes with StatReloader
Watching for file changes with StatReloader
Not Found: /
Not Found: /favicon.ico
Internal Server Error: /trails/
Traceback (most recent call last):
  File "/usr/local/lib/python3.11/site-packages/django/db/backends/utils.py", line 89, in _execute
    return self.cursor.execute(sql, params)
           ^^^^^^^^^^^^^^^^^^^^^^^^^^^^^^^^
psycopg2.errors.UndefinedTable: relation "trails_trail" does not exist
LINE 1: ...rail"."path"::bytea, "trails_trail"."length" FROM "trails_tr...
                                                             ^


The above exception was the direct cause of the following exception:

Traceback (most recent call last):
  File "/usr/local/lib/python3.11/site-packages/django/core/handlers/exception.py", line 55, in inner
    response = get_response(request)
               ^^^^^^^^^^^^^^^^^^^^^
  File "/usr/local/lib/python3.11/site-packages/django/core/handlers/base.py", line 197, in _get_response
    response = wrapped_callback(request, *callback_args, **callback_kwargs)
               ^^^^^^^^^^^^^^^^^^^^^^^^^^^^^^^^^^^^^^^^^^^^^^^^^^^^^^^^^^^^
  File "/usr/src/app/trails/views.py", line 15, in trail_list
    trails_geojson = serialize('geojson', trails, fields=('name', 'path'))
                     ^^^^^^^^^^^^^^^^^^^^^^^^^^^^^^^^^^^^^^^^^^^^^^^^^^^^^
  File "/usr/local/lib/python3.11/site-packages/django/core/serializers/__init__.py", line 134, in serialize
    s.serialize(queryset, **options)
  File "/usr/local/lib/python3.11/site-packages/django/core/serializers/base.py", line 132, in serialize
    for count, obj in enumerate(queryset, start=1):
                      ^^^^^^^^^^^^^^^^^^^^^^^^^^^^
  File "/usr/local/lib/python3.11/site-packages/django/db/models/query.py", line 398, in __iter__
    self._fetch_all()
  File "/usr/local/lib/python3.11/site-packages/django/db/models/query.py", line 1881, in _fetch_all
    self._result_cache = list(self._iterable_class(self))
                         ^^^^^^^^^^^^^^^^^^^^^^^^^^^^^^^^
  File "/usr/local/lib/python3.11/site-packages/django/db/models/query.py", line 91, in __iter__
    results = compiler.execute_sql(
              ^^^^^^^^^^^^^^^^^^^^^
  File "/usr/local/lib/python3.11/site-packages/django/db/models/sql/compiler.py", line 1562, in execute_sql
    cursor.execute(sql, params)
  File "/usr/local/lib/python3.11/site-packages/django/db/backends/utils.py", line 102, in execute
    return super().execute(sql, params)
           ^^^^^^^^^^^^^^^^^^^^^^^^^^^^
  File "/usr/local/lib/python3.11/site-packages/django/db/backends/utils.py", line 67, in execute
    return self._execute_with_wrappers(
           ^^^^^^^^^^^^^^^^^^^^^^^^^^^^
  File "/usr/local/lib/python3.11/site-packages/django/db/backends/utils.py", line 80, in _execute_with_wrappers
    return executor(sql, params, many, context)
           ^^^^^^^^^^^^^^^^^^^^^^^^^^^^^^^^^^^^
  File "/usr/local/lib/python3.11/site-packages/django/db/backends/utils.py", line 84, in _execute
    with self.db.wrap_database_errors:
  File "/usr/local/lib/python3.11/site-packages/django/db/utils.py", line 91, in __exit__
    raise dj_exc_value.with_traceback(traceback) from exc_value
  File "/usr/local/lib/python3.11/site-packages/django/db/backends/utils.py", line 89, in _execute
    return self.cursor.execute(sql, params)
           ^^^^^^^^^^^^^^^^^^^^^^^^^^^^^^^^
django.db.utils.ProgrammingError: relation "trails_trail" does not exist
LINE 1: ...rail"."path"::bytea, "trails_trail"."length" FROM "trails_tr...
                                                             ^

Internal Server Error: /admin/login/
Traceback (most recent call last):
  File "/usr/local/lib/python3.11/site-packages/django/db/backends/utils.py", line 89, in _execute
    return self.cursor.execute(sql, params)
           ^^^^^^^^^^^^^^^^^^^^^^^^^^^^^^^^
psycopg2.errors.UndefinedTable: relation "auth_user" does not exist
LINE 1: ...user"."is_active", "auth_user"."date_joined" FROM "auth_user...
                                                             ^


The above exception was the direct cause of the following exception:

Traceback (most recent call last):
  File "/usr/local/lib/python3.11/site-packages/django/core/handlers/exception.py", line 55, in inner
    response = get_response(request)
               ^^^^^^^^^^^^^^^^^^^^^
  File "/usr/local/lib/python3.11/site-packages/django/core/handlers/base.py", line 197, in _get_response
    response = wrapped_callback(request, *callback_args, **callback_kwargs)
               ^^^^^^^^^^^^^^^^^^^^^^^^^^^^^^^^^^^^^^^^^^^^^^^^^^^^^^^^^^^^
  File "/usr/local/lib/python3.11/site-packages/django/utils/decorators.py", line 46, in _wrapper
    return bound_method(*args, **kwargs)
           ^^^^^^^^^^^^^^^^^^^^^^^^^^^^^
  File "/usr/local/lib/python3.11/site-packages/django/views/decorators/cache.py", line 62, in _wrapper_view_func
    response = view_func(request, *args, **kwargs)
               ^^^^^^^^^^^^^^^^^^^^^^^^^^^^^^^^^^^
  File "/usr/local/lib/python3.11/site-packages/django/contrib/admin/sites.py", line 441, in login
    return LoginView.as_view(**defaults)(request)
           ^^^^^^^^^^^^^^^^^^^^^^^^^^^^^^^^^^^^^^
  File "/usr/local/lib/python3.11/site-packages/django/views/generic/base.py", line 104, in view
    return self.dispatch(request, *args, **kwargs)
           ^^^^^^^^^^^^^^^^^^^^^^^^^^^^^^^^^^^^^^^
  File "/usr/local/lib/python3.11/site-packages/django/utils/decorators.py", line 46, in _wrapper
    return bound_method(*args, **kwargs)
           ^^^^^^^^^^^^^^^^^^^^^^^^^^^^^
  File "/usr/local/lib/python3.11/site-packages/django/views/decorators/debug.py", line 92, in sensitive_post_parameters_wrapper
    return view(request, *args, **kwargs)
           ^^^^^^^^^^^^^^^^^^^^^^^^^^^^^^
  File "/usr/local/lib/python3.11/site-packages/django/utils/decorators.py", line 46, in _wrapper
    return bound_method(*args, **kwargs)
           ^^^^^^^^^^^^^^^^^^^^^^^^^^^^^
  File "/usr/local/lib/python3.11/site-packages/django/utils/decorators.py", line 134, in _wrapper_view
    response = view_func(request, *args, **kwargs)
               ^^^^^^^^^^^^^^^^^^^^^^^^^^^^^^^^^^^
  File "/usr/local/lib/python3.11/site-packages/django/utils/decorators.py", line 46, in _wrapper
    return bound_method(*args, **kwargs)
           ^^^^^^^^^^^^^^^^^^^^^^^^^^^^^
  File "/usr/local/lib/python3.11/site-packages/django/views/decorators/cache.py", line 62, in _wrapper_view_func
    response = view_func(request, *args, **kwargs)
               ^^^^^^^^^^^^^^^^^^^^^^^^^^^^^^^^^^^
  File "/usr/local/lib/python3.11/site-packages/django/contrib/auth/views.py", line 90, in dispatch
    return super().dispatch(request, *args, **kwargs)
           ^^^^^^^^^^^^^^^^^^^^^^^^^^^^^^^^^^^^^^^^^^
  File "/usr/local/lib/python3.11/site-packages/django/views/generic/base.py", line 143, in dispatch
    return handler(request, *args, **kwargs)
           ^^^^^^^^^^^^^^^^^^^^^^^^^^^^^^^^^
  File "/usr/local/lib/python3.11/site-packages/django/views/generic/edit.py", line 152, in post
    if form.is_valid():
       ^^^^^^^^^^^^^^^
  File "/usr/local/lib/python3.11/site-packages/django/forms/forms.py", line 201, in is_valid
    return self.is_bound and not self.errors
                                 ^^^^^^^^^^^
  File "/usr/local/lib/python3.11/site-packages/django/forms/forms.py", line 196, in errors
    self.full_clean()
  File "/usr/local/lib/python3.11/site-packages/django/forms/forms.py", line 434, in full_clean
    self._clean_form()
  File "/usr/local/lib/python3.11/site-packages/django/forms/forms.py", line 455, in _clean_form
    cleaned_data = self.clean()
                   ^^^^^^^^^^^^
  File "/usr/local/lib/python3.11/site-packages/django/contrib/auth/forms.py", line 242, in clean
    self.user_cache = authenticate(
                      ^^^^^^^^^^^^^
  File "/usr/local/lib/python3.11/site-packages/django/views/decorators/debug.py", line 42, in sensitive_variables_wrapper
    return func(*func_args, **func_kwargs)
           ^^^^^^^^^^^^^^^^^^^^^^^^^^^^^^^
  File "/usr/local/lib/python3.11/site-packages/django/contrib/auth/__init__.py", line 77, in authenticate
    user = backend.authenticate(request, **credentials)
           ^^^^^^^^^^^^^^^^^^^^^^^^^^^^^^^^^^^^^^^^^^^^
  File "/usr/local/lib/python3.11/site-packages/django/contrib/auth/backends.py", line 46, in authenticate
    user = UserModel._default_manager.get_by_natural_key(username)
           ^^^^^^^^^^^^^^^^^^^^^^^^^^^^^^^^^^^^^^^^^^^^^^^^^^^^^^^
  File "/usr/local/lib/python3.11/site-packages/django/contrib/auth/base_user.py", line 54, in get_by_natural_key
    return self.get(**{self.model.USERNAME_FIELD: username})
           ^^^^^^^^^^^^^^^^^^^^^^^^^^^^^^^^^^^^^^^^^^^^^^^^^
  File "/usr/local/lib/python3.11/site-packages/django/db/models/manager.py", line 87, in manager_method
    return getattr(self.get_queryset(), name)(*args, **kwargs)
           ^^^^^^^^^^^^^^^^^^^^^^^^^^^^^^^^^^^^^^^^^^^^^^^^^^^
  File "/usr/local/lib/python3.11/site-packages/django/db/models/query.py", line 633, in get
    num = len(clone)
          ^^^^^^^^^^
  File "/usr/local/lib/python3.11/site-packages/django/db/models/query.py", line 380, in __len__
    self._fetch_all()
  File "/usr/local/lib/python3.11/site-packages/django/db/models/query.py", line 1881, in _fetch_all
    self._result_cache = list(self._iterable_class(self))
                         ^^^^^^^^^^^^^^^^^^^^^^^^^^^^^^^^
  File "/usr/local/lib/python3.11/site-packages/django/db/models/query.py", line 91, in __iter__
    results = compiler.execute_sql(
              ^^^^^^^^^^^^^^^^^^^^^
  File "/usr/local/lib/python3.11/site-packages/django/db/models/sql/compiler.py", line 1562, in execute_sql
    cursor.execute(sql, params)
  File "/usr/local/lib/python3.11/site-packages/django/db/backends/utils.py", line 102, in execute
    return super().execute(sql, params)
           ^^^^^^^^^^^^^^^^^^^^^^^^^^^^
  File "/usr/local/lib/python3.11/site-packages/django/db/backends/utils.py", line 67, in execute
    return self._execute_with_wrappers(
           ^^^^^^^^^^^^^^^^^^^^^^^^^^^^
  File "/usr/local/lib/python3.11/site-packages/django/db/backends/utils.py", line 80, in _execute_with_wrappers
    return executor(sql, params, many, context)
           ^^^^^^^^^^^^^^^^^^^^^^^^^^^^^^^^^^^^
  File "/usr/local/lib/python3.11/site-packages/django/db/backends/utils.py", line 84, in _execute
    with self.db.wrap_database_errors:
  File "/usr/local/lib/python3.11/site-packages/django/db/utils.py", line 91, in __exit__
    raise dj_exc_value.with_traceback(traceback) from exc_value
  File "/usr/local/lib/python3.11/site-packages/django/db/backends/utils.py", line 89, in _execute
    return self.cursor.execute(sql, params)
           ^^^^^^^^^^^^^^^^^^^^^^^^^^^^^^^^
django.db.utils.ProgrammingError: relation "auth_user" does not exist
LINE 1: ...user"."is_active", "auth_user"."date_joined" FROM "auth_user...
                                                             ^

Internal Server Error: /trails/
Traceback (most recent call last):
  File "/usr/local/lib/python3.11/site-packages/django/db/backends/utils.py", line 89, in _execute
    return self.cursor.execute(sql, params)
           ^^^^^^^^^^^^^^^^^^^^^^^^^^^^^^^^
psycopg2.errors.UndefinedTable: relation "trails_trail" does not exist
LINE 1: ...rail"."path"::bytea, "trails_trail"."length" FROM "trails_tr...
                                                             ^


The above exception was the direct cause of the following exception:

Traceback (most recent call last):
  File "/usr/local/lib/python3.11/site-packages/django/core/handlers/exception.py", line 55, in inner
    response = get_response(request)
               ^^^^^^^^^^^^^^^^^^^^^
  File "/usr/local/lib/python3.11/site-packages/django/core/handlers/base.py", line 197, in _get_response
    response = wrapped_callback(request, *callback_args, **callback_kwargs)
               ^^^^^^^^^^^^^^^^^^^^^^^^^^^^^^^^^^^^^^^^^^^^^^^^^^^^^^^^^^^^
  File "/usr/src/app/trails/views.py", line 15, in trail_list
    trails_geojson = serialize('geojson', trails, fields=('name', 'path'))
                     ^^^^^^^^^^^^^^^^^^^^^^^^^^^^^^^^^^^^^^^^^^^^^^^^^^^^^
  File "/usr/local/lib/python3.11/site-packages/django/core/serializers/__init__.py", line 134, in serialize
    s.serialize(queryset, **options)
  File "/usr/local/lib/python3.11/site-packages/django/core/serializers/base.py", line 132, in serialize
    for count, obj in enumerate(queryset, start=1):
                      ^^^^^^^^^^^^^^^^^^^^^^^^^^^^
  File "/usr/local/lib/python3.11/site-packages/django/db/models/query.py", line 398, in __iter__
    self._fetch_all()
  File "/usr/local/lib/python3.11/site-packages/django/db/models/query.py", line 1881, in _fetch_all
    self._result_cache = list(self._iterable_class(self))
                         ^^^^^^^^^^^^^^^^^^^^^^^^^^^^^^^^
  File "/usr/local/lib/python3.11/site-packages/django/db/models/query.py", line 91, in __iter__
    results = compiler.execute_sql(
              ^^^^^^^^^^^^^^^^^^^^^
  File "/usr/local/lib/python3.11/site-packages/django/db/models/sql/compiler.py", line 1562, in execute_sql
    cursor.execute(sql, params)
  File "/usr/local/lib/python3.11/site-packages/django/db/backends/utils.py", line 102, in execute
    return super().execute(sql, params)
           ^^^^^^^^^^^^^^^^^^^^^^^^^^^^
  File "/usr/local/lib/python3.11/site-packages/django/db/backends/utils.py", line 67, in execute
    return self._execute_with_wrappers(
           ^^^^^^^^^^^^^^^^^^^^^^^^^^^^
  File "/usr/local/lib/python3.11/site-packages/django/db/backends/utils.py", line 80, in _execute_with_wrappers
    return executor(sql, params, many, context)
           ^^^^^^^^^^^^^^^^^^^^^^^^^^^^^^^^^^^^
  File "/usr/local/lib/python3.11/site-packages/django/db/backends/utils.py", line 84, in _execute
    with self.db.wrap_database_errors:
  File "/usr/local/lib/python3.11/site-packages/django/db/utils.py", line 91, in __exit__
    raise dj_exc_value.with_traceback(traceback) from exc_value
  File "/usr/local/lib/python3.11/site-packages/django/db/backends/utils.py", line 89, in _execute
    return self.cursor.execute(sql, params)
           ^^^^^^^^^^^^^^^^^^^^^^^^^^^^^^^^
django.db.utils.ProgrammingError: relation "trails_trail" does not exist
LINE 1: ...rail"."path"::bytea, "trails_trail"."length" FROM "trails_tr...
                                                             ^

Internal Server Error: /trails/
Traceback (most recent call last):
  File "/usr/local/lib/python3.11/site-packages/django/db/backends/utils.py", line 89, in _execute
    return self.cursor.execute(sql, params)
           ^^^^^^^^^^^^^^^^^^^^^^^^^^^^^^^^
psycopg2.errors.UndefinedTable: relation "trails_trail" does not exist
LINE 1: ...rail"."path"::bytea, "trails_trail"."length" FROM "trails_tr...
                                                             ^


The above exception was the direct cause of the following exception:

Traceback (most recent call last):
  File "/usr/local/lib/python3.11/site-packages/django/core/handlers/exception.py", line 55, in inner
    response = get_response(request)
               ^^^^^^^^^^^^^^^^^^^^^
  File "/usr/local/lib/python3.11/site-packages/django/core/handlers/base.py", line 197, in _get_response
    response = wrapped_callback(request, *callback_args, **callback_kwargs)
               ^^^^^^^^^^^^^^^^^^^^^^^^^^^^^^^^^^^^^^^^^^^^^^^^^^^^^^^^^^^^
  File "/usr/src/app/trails/views.py", line 15, in trail_list
    trails_geojson = serialize('geojson', trails, fields=('name', 'path'))
                     ^^^^^^^^^^^^^^^^^^^^^^^^^^^^^^^^^^^^^^^^^^^^^^^^^^^^^
  File "/usr/local/lib/python3.11/site-packages/django/core/serializers/__init__.py", line 134, in serialize
    s.serialize(queryset, **options)
  File "/usr/local/lib/python3.11/site-packages/django/core/serializers/base.py", line 132, in serialize
    for count, obj in enumerate(queryset, start=1):
                      ^^^^^^^^^^^^^^^^^^^^^^^^^^^^
  File "/usr/local/lib/python3.11/site-packages/django/db/models/query.py", line 398, in __iter__
    self._fetch_all()
  File "/usr/local/lib/python3.11/site-packages/django/db/models/query.py", line 1881, in _fetch_all
    self._result_cache = list(self._iterable_class(self))
                         ^^^^^^^^^^^^^^^^^^^^^^^^^^^^^^^^
  File "/usr/local/lib/python3.11/site-packages/django/db/models/query.py", line 91, in __iter__
    results = compiler.execute_sql(
              ^^^^^^^^^^^^^^^^^^^^^
  File "/usr/local/lib/python3.11/site-packages/django/db/models/sql/compiler.py", line 1562, in execute_sql
    cursor.execute(sql, params)
  File "/usr/local/lib/python3.11/site-packages/django/db/backends/utils.py", line 102, in execute
    return super().execute(sql, params)
           ^^^^^^^^^^^^^^^^^^^^^^^^^^^^
  File "/usr/local/lib/python3.11/site-packages/django/db/backends/utils.py", line 67, in execute
    return self._execute_with_wrappers(
           ^^^^^^^^^^^^^^^^^^^^^^^^^^^^
  File "/usr/local/lib/python3.11/site-packages/django/db/backends/utils.py", line 80, in _execute_with_wrappers
    return executor(sql, params, many, context)
           ^^^^^^^^^^^^^^^^^^^^^^^^^^^^^^^^^^^^
  File "/usr/local/lib/python3.11/site-packages/django/db/backends/utils.py", line 84, in _execute
    with self.db.wrap_database_errors:
  File "/usr/local/lib/python3.11/site-packages/django/db/utils.py", line 91, in __exit__
    raise dj_exc_value.with_traceback(traceback) from exc_value
  File "/usr/local/lib/python3.11/site-packages/django/db/backends/utils.py", line 89, in _execute
    return self.cursor.execute(sql, params)
           ^^^^^^^^^^^^^^^^^^^^^^^^^^^^^^^^
django.db.utils.ProgrammingError: relation "trails_trail" does not exist
LINE 1: ...rail"."path"::bytea, "trails_trail"."length" FROM "trails_tr...
                                                             ^

Not Found: /
Internal Server Error: /trails/
Traceback (most recent call last):
  File "/usr/local/lib/python3.11/site-packages/django/db/backends/utils.py", line 89, in _execute
    return self.cursor.execute(sql, params)
           ^^^^^^^^^^^^^^^^^^^^^^^^^^^^^^^^
psycopg2.errors.UndefinedTable: relation "trails_trail" does not exist
LINE 1: ...rail"."path"::bytea, "trails_trail"."length" FROM "trails_tr...
                                                             ^


The above exception was the direct cause of the following exception:

Traceback (most recent call last):
  File "/usr/local/lib/python3.11/site-packages/django/core/handlers/exception.py", line 55, in inner
    response = get_response(request)
               ^^^^^^^^^^^^^^^^^^^^^
  File "/usr/local/lib/python3.11/site-packages/django/core/handlers/base.py", line 197, in _get_response
    response = wrapped_callback(request, *callback_args, **callback_kwargs)
               ^^^^^^^^^^^^^^^^^^^^^^^^^^^^^^^^^^^^^^^^^^^^^^^^^^^^^^^^^^^^
  File "/usr/src/app/trails/views.py", line 15, in trail_list
    trails_geojson = serialize('geojson', trails, fields=('name', 'path'))
                     ^^^^^^^^^^^^^^^^^^^^^^^^^^^^^^^^^^^^^^^^^^^^^^^^^^^^^
  File "/usr/local/lib/python3.11/site-packages/django/core/serializers/__init__.py", line 134, in serialize
    s.serialize(queryset, **options)
  File "/usr/local/lib/python3.11/site-packages/django/core/serializers/base.py", line 132, in serialize
    for count, obj in enumerate(queryset, start=1):
                      ^^^^^^^^^^^^^^^^^^^^^^^^^^^^
  File "/usr/local/lib/python3.11/site-packages/django/db/models/query.py", line 398, in __iter__
    self._fetch_all()
  File "/usr/local/lib/python3.11/site-packages/django/db/models/query.py", line 1881, in _fetch_all
    self._result_cache = list(self._iterable_class(self))
                         ^^^^^^^^^^^^^^^^^^^^^^^^^^^^^^^^
  File "/usr/local/lib/python3.11/site-packages/django/db/models/query.py", line 91, in __iter__
    results = compiler.execute_sql(
              ^^^^^^^^^^^^^^^^^^^^^
  File "/usr/local/lib/python3.11/site-packages/django/db/models/sql/compiler.py", line 1562, in execute_sql
    cursor.execute(sql, params)
  File "/usr/local/lib/python3.11/site-packages/django/db/backends/utils.py", line 102, in execute
    return super().execute(sql, params)
           ^^^^^^^^^^^^^^^^^^^^^^^^^^^^
  File "/usr/local/lib/python3.11/site-packages/django/db/backends/utils.py", line 67, in execute
    return self._execute_with_wrappers(
           ^^^^^^^^^^^^^^^^^^^^^^^^^^^^
  File "/usr/local/lib/python3.11/site-packages/django/db/backends/utils.py", line 80, in _execute_with_wrappers
    return executor(sql, params, many, context)
           ^^^^^^^^^^^^^^^^^^^^^^^^^^^^^^^^^^^^
  File "/usr/local/lib/python3.11/site-packages/django/db/backends/utils.py", line 84, in _execute
    with self.db.wrap_database_errors:
  File "/usr/local/lib/python3.11/site-packages/django/db/utils.py", line 91, in __exit__
    raise dj_exc_value.with_traceback(traceback) from exc_value
  File "/usr/local/lib/python3.11/site-packages/django/db/backends/utils.py", line 89, in _execute
    return self.cursor.execute(sql, params)
           ^^^^^^^^^^^^^^^^^^^^^^^^^^^^^^^^
django.db.utils.ProgrammingError: relation "trails_trail" does not exist
LINE 1: ...rail"."path"::bytea, "trails_trail"."length" FROM "trails_tr...
                                                             ^

Not Found: /accounts/login/
Watching for file changes with StatReloader
Watching for file changes with StatReloader
Not Found: /
